Workbook
Name lst_ChefsProjet: OFFSET(Data!$A$3,1,0,MAX(1,COUNTA(Data!$A$4:$A$203)),1)
Name lst_Projets: OFFSET(Data!$B$3,1,0,MAX(1,COUNTA(Data!$B$4:$B$203)),1)
Name lst_Types: OFFSET(Data!$C$3,1,0,MAX(1,COUNTA(Data!$C$4:$C$203)),1)
Name lst_Coordinateurs: OFFSET(Data!$D$3,1,0,MAX(1,COUNTA(Data!$D$4:$D$203)),1)
Name lst_Dessinateurs: OFFSET(Data!$E$3,1,0,MAX(1,COUNTA(Data!$E$4:$E$203)),1)
Name lst_Prestataires: OFFSET(Data!$H$3,1,0,MAX(1,COUNTA(Data!$H$4:$H$203)),1)
Name p_Perimetre: Dashboard!$F$5
Name p_Repartition: Dashboard!$R$5
Name p_PremierMois: Dashboard!$AK$5
Name p_HeuresETP: Dashboard!$AU$5
Name p_ChargeFixe: Dashboard!$BD$5
Name lst_Ressources: OFFSET(Calculs!$FA$4,0,0,MAX(1,Calculs!$CD$23+Calculs!$CD$26),1)
Name p_Dessinateur: Dessinateurs!$G$5

Sheet Charge
A1: PLAN DE CHARGE — BUREAU D'ÉTUDES
A2: UNE LIGNE = UNE RESSOURCE sur un sous-projet : un dessinateur (K) OU une ressource externe (L), avec SES heures en M. Pour mettre plusieurs personnes sur un sous-projet, recopier la ligne (colonnes A à J à l'identique) et changer la ressource et les heures. Couleurs : rouge = dessinateur ET externe sur la même ligne (à corriger, seul K est compté) ; orange = aucune ressource (charge à affecter). Insérer, supprimer ou trier des lignes est possible. Les lignes 4 à 27 sont des EXEMPLES FICTIFS à remplacer par vos données.
A3: Chef de projet | B3: Nom du projet | C3: Sous-projet | D3: Produit | E3: Type | F3: Date de besoin | G3: Description du projet | H3: Contraintes, spécifications, délais, budget | I3: Autres informations pertinentes / suggestions d'optimisation des ressources | J3: Coordinateur | K3: Dessinateur projeteur (interne) | L3: OU ressource externe | M3: Heures de cette ressource (h) | N3: Date de début planifiée | O3: Taux d'avancement
A4: Julie Martin | B4: ATLAS | C4: Lot 1 – Structure | D4: Châssis principal | E4: Étude de conception | F4: 46477 | G4: Conception du châssis mécano-soudé de la nouvelle gamme | H4: Masse < 450 kg ; budget étude 60 k€ | I4: Mutualiser les calculs RDM avec le lot 2 | J4: Marc Dubois | K4: Lucas Garnier | M4: 300 | N4: 46328 | O4: 0.15
A5: Julie Martin | B5: ATLAS | C5: Lot 1 – Structure | D5: Châssis principal | E5: Étude de conception | F5: 46477 | G5: Conception du châssis mécano-soudé de la nouvelle gamme | H5: Masse < 450 kg ; budget étude 60 k€ | I5: Mutualiser les calculs RDM avec le lot 2 | J5: Marc Dubois | L5: Paul Girard | M5: 120 | N5: 46328 | O5: 0
A6: Julie Martin | B6: ATLAS | C6: Lot 2 – Carénage | D6: Capots latéraux | E6: Étude de conception | F6: 46535 | G6: Dessin des capots et de leurs fixations | H6: Matière ABS, outillage existant | J6: Marc Dubois | K6: Emma Faure | M6: 260 | N6: 46398 | O6: 0
A7: Julie Martin | B7: ATLAS | C7: Lot 3 – Intégration | D7: Faisceau électrique | E7: Industrialisation | F7: 46598 | G7: Routage des faisceaux et supports | H7: Normes NF C 15-100 | J7: Marc Dubois | L7: Inès Morel | M7: 180 | N7: 46482 | O7: 0
A8: Thomas Bernard | B8: BORÉAL | C8: Phase APD | D8: Groupe froid | E8: Étude de conception | F8: 46416 | G8: Avant-projet détaillé du groupe froid | H8: Délai client ferme | J8: Isabelle Roux | K8: Léa Chevalier | M8: 310 | N8: 46300 | O8: 0.35
A9: Thomas Bernard | B9: BORÉAL | C9: Phase EXE | D9: Groupe froid | E9: Mise à jour de plans | F9: 46507 | G9: Plans d'exécution | H9: Budget 25 k€ | J9: Isabelle Roux | K9: Léa Chevalier | M9: 220 | N9: 46419 | O9: 0
A10: Thomas Bernard | B10: BORÉAL | C10: Phase EXE | D10: Armoire de commande | E10: Modification | F10: 46461 | G10: Reprise de l'armoire existante | J10: Isabelle Roux | L10: Karim Haddad | M10: 90 | N10: 46405 | O10: 0
A11: Sophie Lefèvre | B11: CASSIOPÉE | C11: Rétrofit ligne 2 | D11: Convoyeur | E11: Modification | F11: 46374 | G11: Adaptation du convoyeur au nouveau format | H11: Arrêt de ligne limité à 2 semaines | I11: Réutiliser les plans de la ligne 1 | J11: Marc Dubois | K11: Hugo Mercier | M11: 150 | N11: 46307 | O11: 0.5
A12: Sophie Lefèvre | B12: CASSIOPÉE | C12: Rétrofit ligne 2 | D12: Poste de contrôle | E12: Étude de conception | F12: 46444 | G12: Nouveau poste de contrôle vision | J12: Marc Dubois | K12: Emma Faure | M12: 160 | N12: 46357 | O12: 0.05
A13: Sophie Lefèvre | B13: CASSIOPÉE | C13: Rétrofit ligne 2 | D13: Poste de contrôle | E13: Étude de conception | F13: 46444 | G13: Nouveau poste de contrôle vision | J13: Marc Dubois | L13: Paul Girard | M13: 80 | N13: 46357 | O13: 0
A14: Sophie Lefèvre | B14: DELTA | C14: Lot unique | D14: Bâti machine | E14: Industrialisation | F14: 46568 | G14: Industrialisation du bâti | H14: Cible coût -10 % | J14: Isabelle Roux | K14: Antoine Blanc | M14: 240 | N14: 46433 | O14: 0
A15: Sophie Lefèvre | B15: DELTA | C15: Lot unique | D15: Bâti machine | E15: Industrialisation | F15: 46568 | G15: Industrialisation du bâti | H15: Cible coût -10 % | J15: Isabelle Roux | K15: Hugo Mercier | M15: 120 | N15: 46433 | O15: 0
A16: Nicolas Moreau | B16: ORION | C16: Tranche 1 | D16: Support moteur | E16: Étude de conception | F16: 46353 | G16: Conception du support moteur | J16: Isabelle Roux | K16: Lucas Garnier | M16: 120 | N16: 46279 | O16: 0.8
A17: Nicolas Moreau | B17: ORION | C17: Tranche 1 | D17: Carter de protection | E17: Mise à jour de plans | F17: 46304 | G17: Mise à jour indice C | J17: Isabelle Roux | K17: Lucas Garnier | M17: 40 | N17: 46286 | O17: 1
A18: Nicolas Moreau | B18: ORION | C18: Tranche 2 | D18: Support moteur | E18: Modification | F18: 46521 | G18: Évolution pour moteur 30 kW | J18: Isabelle Roux | K18: Emma Faure | M18: 160 | N18: 46447 | O18: 0
A19: Nicolas Moreau | B19: PÉGASE | C19: Avant-projet | D19: Ensemble complet | E19: Chiffrage / avant-projet | F19: 46367 | G19: Chiffrage et esquisses pour l'appel d'offres | H19: Remise d'offre le 15/12 | J19: Marc Dubois | K19: Léa Chevalier | M19: 70 | N19: 46342 | O19: 0.1
A20: Camille Laurent | B20: PÉGASE | C20: Lot 1 | D20: Ensemble complet | E20: Étude de conception | F20: 46660 | G20: Étude complète si commande | H20: Sous réserve de commande | I20: Renfort externe prévu | J20: Marc Dubois | K20: Hugo Mercier | M20: 300 | N20: 46461 | O20: 0
A21: Camille Laurent | B21: PÉGASE | C21: Lot 1 | D21: Ensemble complet | E21: Étude de conception | F21: 46660 | G21: Étude complète si commande | H21: Sous réserve de commande | I21: Renfort externe prévu | J21: Marc Dubois | L21: Karim Haddad | M21: 180 | N21: 46461 | O21: 0
A22: Camille Laurent | B22: VEGA | C22: Mise en conformité | D22: Garde-corps | E22: Modification | F22: 46402 | G22: Mise en conformité des garde-corps | H22: Norme NF E 85-015 | J22: Isabelle Roux | K22: Antoine Blanc | M22: 85 | N22: 46349 | O22: 0
A23: Camille Laurent | B23: VEGA | C23: Mise en conformité | D23: Passerelle | E23: Mise à jour de plans | F23: 46477 | G23: Plans de recollement | J23: Isabelle Roux | K23: Antoine Blanc | M23: 60 | N23: 46426 | O23: 0
A24: Camille Laurent | B24: VEGA | C24: Mise en conformité | D24: Escalier d'accès | E24: Modification | F24: 46507 | G24: Mise en conformité de l'escalier d'accès | I24: Ressource à définir | J24: Isabelle Roux | M24: 50 | N24: 46447 | O24: 0
A25: Julie Martin | B25: TITAN | C25: Lot 1 | D25: Poutre de levage | E25: Étude de conception | F25: 46295 | G25: Note de calcul et plans | J25: Marc Dubois | K25: Lucas Garnier | M25: 95 | N25: 46258 | O25: 1
A26: Thomas Bernard | B26: DELTA | C26: Lot unique | D26: Habillage | E26: Étude de conception | F26: 46626 | G26: Habillage design | J26: Isabelle Roux | K26: Emma Faure | M26: 120 | N26: 46510 | O26: 0
A27: Thomas Bernard | B27: DELTA | C27: Lot unique | D27: Habillage | E27: Étude de conception | F27: 46626 | G27: Habillage design | J27: Isabelle Roux | L27: Inès Morel | M27: 80 | N27: 46510 | O27: 0

Sheet Data
A1: LISTES DE RÉFÉRENCE
A2: Saisir une valeur par cellule, sans ligne vide, sous chaque en-tête : les listes déroulantes de l'onglet Charge se mettent à jour automatiquement (200 valeurs max par liste). Colonnes F-G et I-J : capacité et charge fixe propres à un dessinateur ou à une ressource externe (vide = valeurs par défaut réglées en haut du Dashboard). Colonne K (facultative) : jours non travaillés communs à tout le bureau (fériés, fermeture), retirés du lissage comme les week-ends. Les valeurs ci-dessous sont des exemples à remplacer.
A3: Chefs de projet | B3: Noms de projet | C3: Types | D3: Coordinateurs | E3: Dessinateurs projeteurs | F3: Capacité mensuelle (h) vide = défaut | G3: Charge fixe hors projet (h/mois) vide = défaut | H3: Ressources externes (personnes) | I3: Capacité mensuelle (h) vide = défaut | J3: Charge fixe hors projet (h/mois) vide = défaut | K3: Jours non travaillés (fériés, fermetures) facultatif
A4: Julie Martin | B4: ATLAS | C4: Étude de conception | D4: Marc Dubois | E4: Lucas Garnier | H4: Paul Girard
A5: Thomas Bernard | B5: BORÉAL | C5: Modification | D5: Isabelle Roux | E5: Emma Faure | H5: Inès Morel
A6: Sophie Lefèvre | B6: CASSIOPÉE | C6: Mise à jour de plans | E6: Hugo Mercier | H6: Karim Haddad
A7: Nicolas Moreau | B7: DELTA | C7: Industrialisation | E7: Léa Chevalier | F7: 96
A8: Camille Laurent | B8: ORION | C8: Chiffrage / avant-projet | E8: Antoine Blanc
B9: PÉGASE
B10: VEGA
B11: TITAN

Sheet Dashboard
C2: TABLEAU DE BORD — PLAN DE CHARGE DU BUREAU D'ÉTUDES | AT2: =TODAY() -> 46313
C3: Synthèse automatique de l'onglet Charge : mettre à jour Charge et Data, le tableau de bord se recalcule seul.
B5: Périmètre | F5: Projets en cours | N5: Répartition | R5: Lissée jusqu'à la date de besoin | AF5: 1er mois affiché | AQ5: Capacité | AU5: 120 | AZ5: Charge fixe | BD5: 20
F6: En cours = avancement < 100 % | R6: =IF(p_Repartition="Tout sur le mois de début","Toute la charge sur le mois de début planifié","Prorata des jours ouvrés entre début planifié et date de besoin") -> Prorata des jours ouvrés entre début planifié et date de besoin | AK6: =IF(ISNUMBER(p_PremierMois),"Saisi manuellement",Calculs!$AL$13) -> 46266 | AU6: par personne | BD6: hors projet
B8: =IF(p_Perimetre="Tous les projets","TOUS LES PROJETS","PROJETS EN COURS") -> PROJETS EN COURS | Z8: =IF(Calculs!$CD$27>0,"Attention : "&Calculs!$CD$27&" ligne(s) de Charge ont un dessinateur ET une ressource externe (en rouge dans Charge)","")
C11: CHEFS DE PROJET | R11: PROGRAMMES SUIVIS | AG11: CHARGE IDENTIFIÉE | AV11: ★ PLUS GROSSE AFFAIRE
C12: =Calculs!$AL$6 -> 5 | R12: =Calculs!$AL$7 -> 7 | AG12: =Calculs!$AL$4 -> 3455 | AV12: =IF(Calculs!$AL$23="",0,INDEX(Calculs!$EP$4:$EP$503,Calculs!$AL$23)) -> 480
C13: =IF(p_Perimetre="Tous les projets","sur l'ensemble des projets","sur les projets en cours") -> sur les projets en cours | R13: projets distincts · classés par charge | AG13: =Calculs!$AL$22 -> 34.55 | AV13: =IF(OR(Calculs!$AL$23="",Calculs!$AL$4=0),0,INDEX(Calculs!$EP$4:$EP$503,Calculs!$AL$23)/Calculs!$AL$4) -> 0.13892909
C15: =Calculs!BL4 -> Julie Martin | L15: =Calculs!BM4 -> 860 | S15: =Calculs!BP4 -> ATLAS | AA15: =Calculs!BQ4 -> 860 | AG15: Réalisé (selon avancement) | AP15: =Calculs!$AL$9 -> 339.5 | AV15: Projet | BA15: =IF(Calculs!$AL$23="","—",INDEX(Charge!$B:$B,Calculs!$AL$23+3)&"") -> PÉGASE
C16: =Calculs!BL5 -> Thomas Bernard | L16: =Calculs!BM5 -> 820 | S16: =Calculs!BP5 -> BORÉAL | AA16: =Calculs!BQ5 -> 620 | AG16: Reste à faire | AP16: =Calculs!$AL$10 -> 3115.5 | AV16: Sous-projet | BA16: =IF(Calculs!$AL$23="","—",INDEX(Charge!$C:$C,Calculs!$AL$23+3)&"") -> Lot 1
C17: =Calculs!BL6 -> Sophie Lefèvre | L17: =Calculs!BM6 -> 750 | S17: =Calculs!BP6 -> DELTA | AA17: =Calculs!BQ6 -> 560 | AV17: Produit | BA17: =IF(Calculs!$AL$23="","—",INDEX(Charge!$D:$D,Calculs!$AL$23+3)&"") -> Ensemble complet
C18: =Calculs!BL7 -> Camille Laurent | L18: =Calculs!BM7 -> 675 | S18: =Calculs!BP7 -> PÉGASE | AA18: =Calculs!BQ7 -> 550 | AG18: PAR TYPE D'AFFAIRE | AV18: Chef de projet | BA18: =IF(Calculs!$AL$23="","—",INDEX(Charge!$A:$A,Calculs!$AL$23+3)&"") -> Camille Laurent
C19: =Calculs!BL8 -> Nicolas Moreau | L19: =Calculs!BM8 -> 350 | S19: =Calculs!BP8 -> CASSIOPÉE | AA19: =Calculs!BQ8 -> 390 | AG19: =Calculs!BT4 -> Étude de conception | AP19: =Calculs!BU4 -> 2030 | AV19: Ressources | BA19: =IF(Calculs!$AL$23="","—",INDEX(Calculs!$ET$4:$ET$503,Calculs!$AL$23)&"") -> 2 dont 1 ext.
C20: =Calculs!BL9 | L20: =Calculs!BM9 | S20: =Calculs!BP9 -> ORION | AA20: =Calculs!BQ9 -> 280 | AG20: =Calculs!BT5 -> Industrialisation | AP20: =Calculs!BU5 -> 540 | AV20: Début planifié | BA20: =IF(Calculs!$AL$23="","",IF(INDEX(Calculs!$EW$4:$EW$503,Calculs!$AL$23)>=2958465,"—",INDEX(Calculs!$EW$4:$EW$503,Calculs!$AL$23))) -> 46461
C21: =Calculs!BL10 | L21: =Calculs!BM10 | S21: =Calculs!BP10 -> VEGA | AA21: =Calculs!BQ10 -> 195 | AG21: =Calculs!BT6 -> Modification | AP21: =Calculs!BU6 -> 535 | AV21: Date de besoin | BA21: =IF(Calculs!$AL$23="","",IF(INDEX(Calculs!$EY$4:$EY$503,Calculs!$AL$23)=0,"—",INDEX(Calculs!$EY$4:$EY$503,Calculs!$AL$23))) -> 46660
C22: =Calculs!BL11 | L22: =Calculs!BM11 | S22: =Calculs!BP11 | AA22: =Calculs!BQ11 | AG22: =Calculs!BT7 -> + 2 autres types | AP22: =Calculs!BU7 -> 350 | AV22: Avancement | BA22: =IF(Calculs!$AL$23="","",INDEX(Calculs!$EU$4:$EU$503,Calculs!$AL$23)) -> 0
B25: INDICATEURS CLÉS
C28: CHARGE TOTALE IDENTIFIÉE | O28: PIC DE CHARGE | AA28: MOIS LE PLUS CHARGÉ | AM28: NOMBRE D'AFFAIRES | AY28: TAUX D'AVANCEMENT MOYEN
C29: =Calculs!$AL$4 -> 3455 | O29: =Calculs!$AL$17 -> 507.8405 | AA29: =IF(Calculs!$AL$17=0,"—",Calculs!$AL$19) -> 46447 | AM29: =Calculs!$AL$5 -> 17 | AY29: =Calculs!$AL$11 -> 0.11120448
C30: =Calculs!$AL$10 -> 3115.5 | O30: =Calculs!$AL$19 -> 46447 | AA30: =Calculs!$AL$20 -> 9 | AM30: =Calculs!$AL$7 -> 7 | AY30: =Calculs!$AL$12 -> 0.098263386
C31: =Calculs!$AL$5 -> 17 | O31: =Calculs!$AL$21 -> 5.078405 | AA31: =Calculs!$AL$26 -> 0.15017462 | AM31: =IF(p_Perimetre="Tous les projets","dont "&Calculs!$AL$24&" ligne(s) terminée(s)",Calculs!$AL$24&" ligne(s) terminée(s) non comptée(s)") -> 2 ligne(s) terminée(s) non comptée(s) | AY31: moyenne simple par affaire
B34: RÉPARTITION DE LA CHARGE
C37: CHARGE EN HEURES PAR MOIS ET PAR PROJET | AI37: RÉPARTITION DE LA CHARGE PAR PROJET
C38: =Calculs!$AL$14 -> 46266 | Q38: =Calculs!$AL$16 -> 73.3 | AI38: Total au centre · une couleur par projet, commune aux deux graphiques
AX42: Projet | BC42: Heures | BF42: Part
AX43: =Calculs!AT4 -> ATLAS | BC43: =IF(Calculs!AT4="","",Calculs!AU4) -> 860 | BF43: =IF(Calculs!AT4="","",Calculs!AV4) -> 0.24891462
AX44: =Calculs!AT5 -> BORÉAL | BC44: =IF(Calculs!AT5="","",Calculs!AU5) -> 620 | BF44: =IF(Calculs!AT5="","",Calculs!AV5) -> 0.17945007
AI45: =Calculs!$AL$4 -> 3455 | AX45: =Calculs!AT6 -> DELTA | BC45: =IF(Calculs!AT6="","",Calculs!AU6) -> 560 | BF45: =IF(Calculs!AT6="","",Calculs!AV6) -> 0.16208394
AX46: =Calculs!AT7 -> PÉGASE | BC46: =IF(Calculs!AT7="","",Calculs!AU7) -> 550 | BF46: =IF(Calculs!AT7="","",Calculs!AV7) -> 0.15918958
AI47: au total | AX47: =Calculs!AT8 -> CASSIOPÉE | BC47: =IF(Calculs!AT8="","",Calculs!AU8) -> 390 | BF47: =IF(Calculs!AT8="","",Calculs!AV8) -> 0.11287988
AX48: =Calculs!AT9 -> ORION | BC48: =IF(Calculs!AT9="","",Calculs!AU9) -> 280 | BF48: =IF(Calculs!AT9="","",Calculs!AV9) -> 0.081041968
AX49: =Calculs!AT10 -> VEGA | BC49: =IF(Calculs!AT10="","",Calculs!AU10) -> 195 | BF49: =IF(Calculs!AT10="","",Calculs!AV10) -> 0.056439942
AX50: =Calculs!AT11 | BC50: =IF(Calculs!AT11="","",Calculs!AU11) | BF50: =IF(Calculs!AT11="","",Calculs!AV11)
AX51: =Calculs!AT12 | BC51: =IF(Calculs!AT12="","",Calculs!AU12) | BF51: =IF(Calculs!AT12="","",Calculs!AV12)
B57: LISTE DES AFFAIRES (un sous-projet par ligne, toutes ressources regroupées, par charge décroissante)
B59: N° | D59: Projet | L59: Sous-projet | T59: Produit | AB59: Chef de projet | AI59: Ressources | AM59: Charge (h) | AR59: % de la charge totale | AX59: Avancement | BD59: Date de début planifiée
B60: =IF(Calculs!$BX$4="","",Calculs!$BW$4) -> 1 | D60: =IF(Calculs!$BX$4="","",INDEX(Charge!$B:$B,Calculs!$BX$4+3)&"") -> PÉGASE | L60: =IF(Calculs!$BX$4="","",INDEX(Charge!$C:$C,Calculs!$BX$4+3)&"") -> Lot 1 | T60: =IF(Calculs!$BX$4="","",INDEX(Charge!$D:$D,Calculs!$BX$4+3)&"") -> Ensemble complet | AB60: =IF(Calculs!$BX$4="","",INDEX(Charge!$A:$A,Calculs!$BX$4+3)&"") -> Camille Laurent | AI60: =IF(Calculs!$BX$4="","",INDEX(Calculs!$ET$4:$ET$503,Calculs!$BX$4)) -> 2 dont 1 ext. | AM60: =IF(Calculs!$BX$4="","",INDEX(Calculs!$EP$4:$EP$503,Calculs!$BX$4)) -> 480 | AR60: =IF(Calculs!$BX$4="","",IF(Calculs!$AL$4=0,0,INDEX(Calculs!$EP$4:$EP$503,Calculs!$BX$4)/Calculs!$AL$4)) -> 0.13892909 | AX60: =IF(Calculs!$BX$4="","",INDEX(Calculs!$EU$4:$EU$503,Calculs!$BX$4)) -> 0 | BD60: =IF(Calculs!$BX$4="","",IF(INDEX(Calculs!$EW$4:$EW$503,Calculs!$BX$4)>=2958465,"à planifier",INDEX(Calculs!$EW$4:$EW$503,Calculs!$BX$4))) -> 46461
B61: =IF(Calculs!$BX$5="","",Calculs!$BW$5) -> 2 | D61: =IF(Calculs!$BX$5="","",INDEX(Charge!$B:$B,Calculs!$BX$5+3)&"") -> ATLAS | L61: =IF(Calculs!$BX$5="","",INDEX(Charge!$C:$C,Calculs!$BX$5+3)&"") -> Lot 1 – Structure | T61: =IF(Calculs!$BX$5="","",INDEX(Charge!$D:$D,Calculs!$BX$5+3)&"") -> Châssis principal | AB61: =IF(Calculs!$BX$5="","",INDEX(Charge!$A:$A,Calculs!$BX$5+3)&"") -> Julie Martin | AI61: =IF(Calculs!$BX$5="","",INDEX(Calculs!$ET$4:$ET$503,Calculs!$BX$5)) -> 2 dont 1 ext. | AM61: =IF(Calculs!$BX$5="","",INDEX(Calculs!$EP$4:$EP$503,Calculs!$BX$5)) -> 420 | AR61: =IF(Calculs!$BX$5="","",IF(Calculs!$AL$4=0,0,INDEX(Calculs!$EP$4:$EP$503,Calculs!$BX$5)/Calculs!$AL$4)) -> 0.12156295 | AX61: =IF(Calculs!$BX$5="","",INDEX(Calculs!$EU$4:$EU$503,Calculs!$BX$5)) -> 0.10714286 | BD61: =IF(Calculs!$BX$5="","",IF(INDEX(Calculs!$EW$4:$EW$503,Calculs!$BX$5)>=2958465,"à planifier",INDEX(Calculs!$EW$4:$EW$503,Calculs!$BX$5))) -> 46328
B62: =IF(Calculs!$BX$6="","",Calculs!$BW$6) -> 3 | D62: =IF(Calculs!$BX$6="","",INDEX(Charge!$B:$B,Calculs!$BX$6+3)&"") -> DELTA | L62: =IF(Calculs!$BX$6="","",INDEX(Charge!$C:$C,Calculs!$BX$6+3)&"") -> Lot unique | T62: =IF(Calculs!$BX$6="","",INDEX(Charge!$D:$D,Calculs!$BX$6+3)&"") -> Bâti machine | AB62: =IF(Calculs!$BX$6="","",INDEX(Charge!$A:$A,Calculs!$BX$6+3)&"") -> Sophie Lefèvre | AI62: =IF(Calculs!$BX$6="","",INDEX(Calculs!$ET$4:$ET$503,Calculs!$BX$6)) -> 2 | AM62: =IF(Calculs!$BX$6="","",INDEX(Calculs!$EP$4:$EP$503,Calculs!$BX$6)) -> 360 | AR62: =IF(Calculs!$BX$6="","",IF(Calculs!$AL$4=0,0,INDEX(Calculs!$EP$4:$EP$503,Calculs!$BX$6)/Calculs!$AL$4)) -> 0.10419682 | AX62: =IF(Calculs!$BX$6="","",INDEX(Calculs!$EU$4:$EU$503,Calculs!$BX$6)) -> 0 | BD62: =IF(Calculs!$BX$6="","",IF(INDEX(Calculs!$EW$4:$EW$503,Calculs!$BX$6)>=2958465,"à planifier",INDEX(Calculs!$EW$4:$EW$503,Calculs!$BX$6))) -> 46433
B63: =IF(Calculs!$BX$7="","",Calculs!$BW$7) -> 4 | D63: =IF(Calculs!$BX$7="","",INDEX(Charge!$B:$B,Calculs!$BX$7+3)&"") -> BORÉAL | L63: =IF(Calculs!$BX$7="","",INDEX(Charge!$C:$C,Calculs!$BX$7+3)&"") -> Phase APD | T63: =IF(Calculs!$BX$7="","",INDEX(Charge!$D:$D,Calculs!$BX$7+3)&"") -> Groupe froid | AB63: =IF(Calculs!$BX$7="","",INDEX(Charge!$A:$A,Calculs!$BX$7+3)&"") -> Thomas Bernard | AI63: =IF(Calculs!$BX$7="","",INDEX(Calculs!$ET$4:$ET$503,Calculs!$BX$7)) -> 1 | AM63: =IF(Calculs!$BX$7="","",INDEX(Calculs!$EP$4:$EP$503,Calculs!$BX$7)) -> 310 | AR63: =IF(Calculs!$BX$7="","",IF(Calculs!$AL$4=0,0,INDEX(Calculs!$EP$4:$EP$503,Calculs!$BX$7)/Calculs!$AL$4)) -> 0.089725036 | AX63: =IF(Calculs!$BX$7="","",INDEX(Calculs!$EU$4:$EU$503,Calculs!$BX$7)) -> 0.35 | BD63: =IF(Calculs!$BX$7="","",IF(INDEX(Calculs!$EW$4:$EW$503,Calculs!$BX$7)>=2958465,"à planifier",INDEX(Calculs!$EW$4:$EW$503,Calculs!$BX$7))) -> 46300
...

Sheet Dessinateurs
C2: CHARGE PAR RESSOURCE (DESSINATEURS ET EXTERNES) | AT2: =TODAY() -> 46313
C3: Charge fixe hors projet + heures de ses lignes dans l'onglet Charge, comparées à la capacité mensuelle de la personne.
B5: Ressource | G5: Lucas Garnier | T5: Capacité | X5: =Calculs!$CD$6 -> 120 | AC5: Charge fixe | AH5: =Calculs!$CD$7 -> 20 | AL5: Dispo. projets | AS5: =Calculs!$CD$8 -> 100 | AX5: =Calculs!$CD$22 -> 46266
G6: =IF(Calculs!$CD$25="Hors liste","Absent des listes Data : réglages par défaut",IF(Calculs!$CD$25="Externe","Ressource externe (Data, colonne H)","Dessinateur interne (Data, colonne E)")) -> Dessinateur interne (Data, colonne E) | T6: par mois · valeurs propres à la personne (Data, colonnes F-G ou I-J) ou valeurs par défaut du Dashboard | AX6: ="Périmètre : "&Calculs!$CD$21 -> Périmètre : Projets en cours
B8: =IF(Calculs!$CD$4="","SYNTHÈSE — choisir une ressource","SYNTHÈSE — "&UPPER(Calculs!$CD$4)&IF(Calculs!$CD$25="Externe"," (RESSOURCE EXTERNE)","")) -> SYNTHÈSE — LUCAS GARNIER | AF8: =IF(Calculs!$CD$27>0,"Attention : "&Calculs!$CD$27&" ligne(s) de Charge ont un dessinateur ET une ressource externe (en rouge dans Charge)","")
C11: CAPACITÉ MENSUELLE | O11: CHARGE PROJETS AFFECTÉE | AA11: MOIS LE PLUS CHARGÉ | AM11: MOIS EN SURCHARGE | AY11: OCCUPATION MOYENNE
C12: =Calculs!$CD$6 -> 120 | O12: =Calculs!$CD$9 -> 420 | AA12: =IF(OR(Calculs!$CD$4="",Calculs!$CD$11=0),"—",Calculs!$CD$14) -> 46327 | AM12: =Calculs!$CD$16 -> 1 | AY12: =Calculs!$CD$19 -> 0.45833333
C13: =Calculs!$CD$7 -> 20 | O13: =Calculs!$CD$10 -> 2 | AA13: =Calculs!$CD$12 -> 121.9697 | AM13: =Calculs!$CD$17 -> 2 | AY13: =Calculs!$CD$18 -> 782
C14: =IF(AND(Calculs!$CD$4<>"",Calculs!$CD$7>=Calculs!$CD$6),"Attention : charge fixe ≥ capacité",Calculs!$CD$8) -> 100 | O14: =Calculs!$CD$11 -> 420 | AA14: =Calculs!$CD$15 -> 1.0166667 | AM14: =IF(Calculs!$CD$16=0,"Aucun dépassement prévu",Calculs!$CD$20) -> 46327 | AY14: sur les 12 mois affichés
B17: CHARGE MENSUELLE
C20: =IF(Calculs!$CD$4="","CHARGE MENSUELLE (HEURES)","CHARGE MENSUELLE DE "&UPPER(Calculs!$CD$4)&" (HEURES)") -> CHARGE MENSUELLE DE LUCAS GARNIER (HEURES)
D21: Charge fixe hors projet | O21: Charge projets | Z21: Dépassement de capacité | AM21: Capacité mensuelle
C39: Heures par mois | L39: =Calculs!CG4 -> 46266 | P39: =Calculs!CG5 -> 46296 | T39: =Calculs!CG6 -> 46327 | X39: =Calculs!CG7 -> 46357 | AB39: =Calculs!CG8 -> 46388 | AF39: =Calculs!CG9 -> 46419 | AJ39: =Calculs!CG10 -> 46447 | AN39: =Calculs!CG11 -> 46478 | AR39: =Calculs!CG12 -> 46508 | AV39: =Calculs!CG13 -> 46539 | AZ39: =Calculs!CG14 -> 46569 | BD39: =Calculs!CG15 -> 46600
C40: Charge fixe hors projet | L40: =Calculs!CH4 -> 20 | P40: =Calculs!CH5 -> 20 | T40: =Calculs!CH6 -> 20 | X40: =Calculs!CH7 -> 20 | AB40: =Calculs!CH8 -> 20 | AF40: =Calculs!CH9 -> 20 | AJ40: =Calculs!CH10 -> 20 | AN40: =Calculs!CH11 -> 20 | AR40: =Calculs!CH12 -> 20 | AV40: =Calculs!CH13 -> 20 | AZ40: =Calculs!CH14 -> 20 | BD40: =Calculs!CH15 -> 20
C41: Charge projets | L41: =Calculs!CI4 -> 28.363636 | P41: =Calculs!CI5 -> 48 | T41: =Calculs!CI6 -> 101.9697 | X41: =Calculs!CI7 -> 63.888889 | AB41: =Calculs!CI8 -> 58.333333 | AF41: =Calculs!CI9 -> 55.555556 | AJ41: =Calculs!CI10 -> 63.888889 | AN41: =Calculs!CI11 -> 0 | AR41: =Calculs!CI12 -> 0 | AV41: =Calculs!CI13 -> 0 | AZ41: =Calculs!CI14 -> 0 | BD41: =Calculs!CI15 -> 0
C42: Charge totale | L42: =Calculs!CJ4 -> 48.363636 | P42: =Calculs!CJ5 -> 68 | T42: =Calculs!CJ6 -> 121.9697 | X42: =Calculs!CJ7 -> 83.888889 | AB42: =Calculs!CJ8 -> 78.333333 | AF42: =Calculs!CJ9 -> 75.555556 | AJ42: =Calculs!CJ10 -> 83.888889 | AN42: =Calculs!CJ11 -> 20 | AR42: =Calculs!CJ12 -> 20 | AV42: =Calculs!CJ13 -> 20 | AZ42: =Calculs!CJ14 -> 20 | BD42: =Calculs!CJ15 -> 20
C43: Capacité | L43: =Calculs!CK4 -> 120 | P43: =Calculs!CK5 -> 120 | T43: =Calculs!CK6 -> 120 | X43: =Calculs!CK7 -> 120 | AB43: =Calculs!CK8 -> 120 | AF43: =Calculs!CK9 -> 120 | AJ43: =Calculs!CK10 -> 120 | AN43: =Calculs!CK11 -> 120 | AR43: =Calculs!CK12 -> 120 | AV43: =Calculs!CK13 -> 120 | AZ43: =Calculs!CK14 -> 120 | BD43: =Calculs!CK15 -> 120
C44: Marge (+) / dépassement (−) | L44: =Calculs!CN4 -> 72 | P44: =Calculs!CN5 -> 52 | T44: =Calculs!CN6 -> -2 | X44: =Calculs!CN7 -> 36 | AB44: =Calculs!CN8 -> 42 | AF44: =Calculs!CN9 -> 44 | AJ44: =Calculs!CN10 -> 36 | AN44: =Calculs!CN11 -> 100 | AR44: =Calculs!CN12 -> 100 | AV44: =Calculs!CN13 -> 100 | AZ44: =Calculs!CN14 -> 100 | BD44: =Calculs!CN15 -> 100
C45: Occupation | L45: =Calculs!CO4 -> 0.4 | P45: =Calculs!CO5 -> 0.56666667 | T45: =Calculs!CO6 -> 1.0166667 | X45: =Calculs!CO7 -> 0.7 | AB45: =Calculs!CO8 -> 0.65 | AF45: =Calculs!CO9 -> 0.63333333 | AJ45: =Calculs!CO10 -> 0.7 | AN45: =Calculs!CO11 -> 0.16666667 | AR45: =Calculs!CO12 -> 0.16666667 | AV45: =Calculs!CO13 -> 0.16666667 | AZ45: =Calculs!CO14 -> 0.16666667 | BD45: =Calculs!CO15 -> 0.16666667
B48: =IF(Calculs!$CD$4="","AFFAIRES DE LA RESSOURCE","AFFAIRES DE "&UPPER(Calculs!$CD$4)&" (par charge décroissante)") -> AFFAIRES DE LUCAS GARNIER (par charge décroissante)
B50: N° | D50: Projet | M50: Sous-projet | V50: Produit | AE50: Chef de projet | AL50: Charge (h) | AQ50: Heures sur la période | AW50: Début planifié | BA50: Date de besoin | BE50: Avancement
B51: =IF(Calculs!$DY$4="","",Calculs!DX4) -> 1 | D51: =IF(Calculs!$DY$4="","",Calculs!DZ4) -> ATLAS | M51: =IF(Calculs!$DY$4="","",Calculs!EA4) -> Lot 1 – Structure | V51: =IF(Calculs!$DY$4="","",Calculs!EB4) -> Châssis principal | AE51: =IF(Calculs!$DY$4="","",Calculs!EC4) -> Julie Martin | AL51: =IF(Calculs!$DY$4="","",Calculs!ED4) -> 300 | AQ51: =IF(Calculs!$DY$4="","",Calculs!EE4) -> 300 | AW51: =IF(Calculs!$DY$4="","",Calculs!EF4) -> 46328 | BA51: =IF(Calculs!$DY$4="","",Calculs!EG4) -> 46477 | BE51: =IF(Calculs!$DY$4="","",Calculs!EH4) -> 0.15
B52: =IF(Calculs!$DY$5="","",Calculs!DX5) -> 2 | D52: =IF(Calculs!$DY$5="","",Calculs!DZ5) -> ORION | M52: =IF(Calculs!$DY$5="","",Calculs!EA5) -> Tranche 1 | V52: =IF(Calculs!$DY$5="","",Calculs!EB5) -> Support moteur | AE52: =IF(Calculs!$DY$5="","",Calculs!EC5) -> Nicolas Moreau | AL52: =IF(Calculs!$DY$5="","",Calculs!ED5) -> 120 | AQ52: =IF(Calculs!$DY$5="","",Calculs!EE5) -> 120 | AW52: =IF(Calculs!$DY$5="","",Calculs!EF5) -> 46279 | BA52: =IF(Calculs!$DY$5="","",Calculs!EG5) -> 46353 | BE52: =IF(Calculs!$DY$5="","",Calculs!EH5) -> 0.8
B53: =IF(Calculs!$DY$6="","",Calculs!DX6) | D53: =IF(Calculs!$DY$6="","",Calculs!DZ6) | M53: =IF(Calculs!$DY$6="","",Calculs!EA6) | V53: =IF(Calculs!$DY$6="","",Calculs!EB6) | AE53: =IF(Calculs!$DY$6="","",Calculs!EC6) | AL53: =IF(Calculs!$DY$6="","",Calculs!ED6) | AQ53: =IF(Calculs!$DY$6="","",Calculs!EE6) | AW53: =IF(Calculs!$DY$6="","",Calculs!EF6) | BA53: =IF(Calculs!$DY$6="","",Calculs!EG6) | BE53: =IF(Calculs!$DY$6="","",Calculs!EH6)
B54: =IF(Calculs!$DY$7="","",Calculs!DX7) | D54: =IF(Calculs!$DY$7="","",Calculs!DZ7) | M54: =IF(Calculs!$DY$7="","",Calculs!EA7) | V54: =IF(Calculs!$DY$7="","",Calculs!EB7) | AE54: =IF(Calculs!$DY$7="","",Calculs!EC7) | AL54: =IF(Calculs!$DY$7="","",Calculs!ED7) | AQ54: =IF(Calculs!$DY$7="","",Calculs!EE7) | AW54: =IF(Calculs!$DY$7="","",Calculs!EF7) | BA54: =IF(Calculs!$DY$7="","",Calculs!EG7) | BE54: =IF(Calculs!$DY$7="","",Calculs!EH7)
B55: =IF(Calculs!$DY$8="","",Calculs!DX8) | D55: =IF(Calculs!$DY$8="","",Calculs!DZ8) | M55: =IF(Calculs!$DY$8="","",Calculs!EA8) | V55: =IF(Calculs!$DY$8="","",Calculs!EB8) | AE55: =IF(Calculs!$DY$8="","",Calculs!EC8) | AL55: =IF(Calculs!$DY$8="","",Calculs!ED8) | AQ55: =IF(Calculs!$DY$8="","",Calculs!EE8) | AW55: =IF(Calculs!$DY$8="","",Calculs!EF8) | BA55: =IF(Calculs!$DY$8="","",Calculs!EG8) | BE55: =IF(Calculs!$DY$8="","",Calculs!EH8)
B56: =IF(Calculs!$DY$9="","",Calculs!DX9) | D56: =IF(Calculs!$DY$9="","",Calculs!DZ9) | M56: =IF(Calculs!$DY$9="","",Calculs!EA9) | V56: =IF(Calculs!$DY$9="","",Calculs!EB9) | AE56: =IF(Calculs!$DY$9="","",Calculs!EC9) | AL56: =IF(Calculs!$DY$9="","",Calculs!ED9) | AQ56: =IF(Calculs!$DY$9="","",Calculs!EE9) | AW56: =IF(Calculs!$DY$9="","",Calculs!EF9) | BA56: =IF(Calculs!$DY$9="","",Calculs!EG9) | BE56: =IF(Calculs!$DY$9="","",Calculs!EH9)
B57: =IF(Calculs!$DY$10="","",Calculs!DX10) | D57: =IF(Calculs!$DY$10="","",Calculs!DZ10) | M57: =IF(Calculs!$DY$10="","",Calculs!EA10) | V57: =IF(Calculs!$DY$10="","",Calculs!EB10) | AE57: =IF(Calculs!$DY$10="","",Calculs!EC10) | AL57: =IF(Calculs!$DY$10="","",Calculs!ED10) | AQ57: =IF(Calculs!$DY$10="","",Calculs!EE10) | AW57: =IF(Calculs!$DY$10="","",Calculs!EF10) | BA57: =IF(Calculs!$DY$10="","",Calculs!EG10) | BE57: =IF(Calculs!$DY$10="","",Calculs!EH10)
B58: =IF(Calculs!$DY$11="","",Calculs!DX11) | D58: =IF(Calculs!$DY$11="","",Calculs!DZ11) | M58: =IF(Calculs!$DY$11="","",Calculs!EA11) | V58: =IF(Calculs!$DY$11="","",Calculs!EB11) | AE58: =IF(Calculs!$DY$11="","",Calculs!EC11) | AL58: =IF(Calculs!$DY$11="","",Calculs!ED11) | AQ58: =IF(Calculs!$DY$11="","",Calculs!EE11) | AW58: =IF(Calculs!$DY$11="","",Calculs!EF11) | BA58: =IF(Calculs!$DY$11="","",Calculs!EG11) | BE58: =IF(Calculs!$DY$11="","",Calculs!EH11)
B59: =IF(Calculs!$DY$12="","",Calculs!DX12) | D59: =IF(Calculs!$DY$12="","",Calculs!DZ12) | M59: =IF(Calculs!$DY$12="","",Calculs!EA12) | V59: =IF(Calculs!$DY$12="","",Calculs!EB12) | AE59: =IF(Calculs!$DY$12="","",Calculs!EC12) | AL59: =IF(Calculs!$DY$12="","",Calculs!ED12) | AQ59: =IF(Calculs!$DY$12="","",Calculs!EE12) | AW59: =IF(Calculs!$DY$12="","",Calculs!EF12) | BA59: =IF(Calculs!$DY$12="","",Calculs!EG12) | BE59: =IF(Calculs!$DY$12="","",Calculs!EH12)
B60: =IF(Calculs!$DY$13="","",Calculs!DX13) | D60: =IF(Calculs!$DY$13="","",Calculs!DZ13) | M60: =IF(Calculs!$DY$13="","",Calculs!EA13) | V60: =IF(Calculs!$DY$13="","",Calculs!EB13) | AE60: =IF(Calculs!$DY$13="","",Calculs!EC13) | AL60: =IF(Calculs!$DY$13="","",Calculs!ED13) | AQ60: =IF(Calculs!$DY$13="","",Calculs!EE13) | AW60: =IF(Calculs!$DY$13="","",Calculs!EF13) | BA60: =IF(Calculs!$DY$13="","",Calculs!EG13) | BE60: =IF(Calculs!$DY$13="","",Calculs!EH13)
B61: =IF(Calculs!$DY$14="","",Calculs!DX14) | D61: =IF(Calculs!$DY$14="","",Calculs!DZ14) | M61: =IF(Calculs!$DY$14="","",Calculs!EA14) | V61: =IF(Calculs!$DY$14="","",Calculs!EB14) | AE61: =IF(Calculs!$DY$14="","",Calculs!EC14) | AL61: =IF(Calculs!$DY$14="","",Calculs!ED14) | AQ61: =IF(Calculs!$DY$14="","",Calculs!EE14) | AW61: =IF(Calculs!$DY$14="","",Calculs!EF14) | BA61: =IF(Calculs!$DY$14="","",Calculs!EG14) | BE61: =IF(Calculs!$DY$14="","",Calculs!EH14)
B62: =IF(Calculs!$DY$15="","",Calculs!DX15) | D62: =IF(Calculs!$DY$15="","",Calculs!DZ15) | M62: =IF(Calculs!$DY$15="","",Calculs!EA15) | V62: =IF(Calculs!$DY$15="","",Calculs!EB15) | AE62: =IF(Calculs!$DY$15="","",Calculs!EC15) | AL62: =IF(Calculs!$DY$15="","",Calculs!ED15) | AQ62: =IF(Calculs!$DY$15="","",Calculs!EE15) | AW62: =IF(Calculs!$DY$15="","",Calculs!EF15) | BA62: =IF(Calculs!$DY$15="","",Calculs!EG15) | BE62: =IF(Calculs!$DY$15="","",Calculs!EH15)
B63: =IF(Calculs!$DY$16="","",Calculs!DX16) | D63: =IF(Calculs!$DY$16="","",Calculs!DZ16) | M63: =IF(Calculs!$DY$16="","",Calculs!EA16) | V63: =IF(Calculs!$DY$16="","",Calculs!EB16) | AE63: =IF(Calculs!$DY$16="","",Calculs!EC16) | AL63: =IF(Calculs!$DY$16="","",Calculs!ED16) | AQ63: =IF(Calculs!$DY$16="","",Calculs!EE16) | AW63: =IF(Calculs!$DY$16="","",Calculs!EF16) | BA63: =IF(Calculs!$DY$16="","",Calculs!EG16) | BE63: =IF(Calculs!$DY$16="","",Calculs!EH16)
B64: =IF(Calculs!$DY$17="","",Calculs!DX17) | D64: =IF(Calculs!$DY$17="","",Calculs!DZ17) | M64: =IF(Calculs!$DY$17="","",Calculs!EA17) | V64: =IF(Calculs!$DY$17="","",Calculs!EB17) | AE64: =IF(Calculs!$DY$17="","",Calculs!EC17) | AL64: =IF(Calculs!$DY$17="","",Calculs!ED17) | AQ64: =IF(Calculs!$DY$17="","",Calculs!EE17) | AW64: =IF(Calculs!$DY$17="","",Calculs!EF17) | BA64: =IF(Calculs!$DY$17="","",Calculs!EG17) | BE64: =IF(Calculs!$DY$17="","",Calculs!EH17)
B65: =IF(Calculs!$DY$18="","",Calculs!DX18) | D65: =IF(Calculs!$DY$18="","",Calculs!DZ18) | M65: =IF(Calculs!$DY$18="","",Calculs!EA18) | V65: =IF(Calculs!$DY$18="","",Calculs!EB18) | AE65: =IF(Calculs!$DY$18="","",Calculs!EC18) | AL65: =IF(Calculs!$DY$18="","",Calculs!ED18) | AQ65: =IF(Calculs!$DY$18="","",Calculs!EE18) | AW65: =IF(Calculs!$DY$18="","",Calculs!EF18) | BA65: =IF(Calculs!$DY$18="","",Calculs!EG18) | BE65: =IF(Calculs!$DY$18="","",Calculs!EH18)
B66: =IF(Calculs!$CD$28>15,"Seules les 15 plus grosses lignes sont listées sur "&Calculs!$CD$28&".",IF(AND(Calculs!$CD$4<>"",Calculs!$CD$28=0),"Aucune affaire affectée à cette ressource dans le périmètre.",""))
B68: OCCUPATION DE L'ÉQUIPE (charge fixe + projets, en % de la capacité)
C71: Vert : moins de 90 % · Orange : de 90 à 100 % · Rouge : au-delà de 100 % (surcharge) · les 16 premières ressources des listes Data (dessinateurs puis externes)
C72: Ressource | L72: =Calculs!CW3 -> 46266 | P72: =Calculs!CX3 -> 46296 | T72: =Calculs!CY3 -> 46327 | X72: =Calculs!CZ3 -> 46357 | AB72: =Calculs!DA3 -> 46388 | AF72: =Calculs!DB3 -> 46419 | AJ72: =Calculs!DC3 -> 46447 | AN72: =Calculs!DD3 -> 46478 | AR72: =Calculs!DE3 -> 46508 | AV72: =Calculs!DF3 -> 46539 | AZ72: =Calculs!DG3 -> 46569 | BD72: =Calculs!DH3 -> 46600
...

Sheet Calculs
A1: CALCULS INTERMÉDIAIRES — alimentent le Dashboard, ne pas modifier
V2: Fin de mois → | W2: =EOMONTH(W3,0) -> 46295 | X2: =EOMONTH(X3,0) -> 46326 | Y2: =EOMONTH(Y3,0) -> 46356 | Z2: =EOMONTH(Z3,0) -> 46387 | AA2: =EOMONTH(AA3,0) -> 46418 | AB2: =EOMONTH(AB3,0) -> 46446 | AC2: =EOMONTH(AC3,0) -> 46477 | AD2: =EOMONTH(AD3,0) -> 46507 | ... AH2: =EOMONTH(AH3,0) -> 46630 | CW2: Heures projets par mois → | DI2: Occupation (charge fixe + projets) / capacité →
A3: Ligne (onglet Charge) | B3: Affaire valide (projet renseigné) | C3: Avancement (0-1) | D3: Incluse dans le périmètre | E3: Charge incluse (h) | F3: Chef de projet | G3: Projet | H3: Type | I3: Début planifié | J3: Fin de répartition | K3: Jours ouvrés de la période | L3: Rang affaire (charge décroissante) | M3: 1re occurrence chef | N3: Charge du chef | O3: Rang chef | P3: 1re occurrence projet | Q3: Charge du projet | R3: Rang projet | S3: 1re occurrence type | T3: Charge du type | U3: Rang type | V3: Groupe couleur (projet) | W3: =$AL$14 -> 46266 | X3: =EDATE(W3,1) -> 46296 | Y3: =EDATE(X3,1) -> 46327 | Z3: =EDATE(Y3,1) -> 46357 | AA3: =EDATE(Z3,1) -> 46388 | AB3: =EDATE(AA3,1) -> 46419 | AC3: =EDATE(AB3,1) -> 46447 | AD3: =EDATE(AC3,1) -> 46478 | AE3: =EDATE(AD3,1) -> 46508 | ... AH3: =EDATE(AG3,1) -> 46600 | AI3: Charge sur la période (h) | AK3: Indicateur | AL3: Valeur | AN3: N° mois | AO3: Mois | AP3: Charge (h) | AQ3: Affaires actives | AS3: Groupe | AT3: Projet | AU3: Charge (h) | AV3: Part | AW3: =W$3 -> 46266 | AX3: =X$3 -> 46296 | AY3: =Y$3 -> 46327 | AZ3: =Z$3 -> 46357 | BA3: =AA$3 -> 46388 | BB3: =AB$3 -> 46419 | BC3: =AC$3 -> 46447 | BD3: =AD$3 -> 46478 | ... BH3: =AH$3 -> 46600 | BK3: Rang | BL3: Chef de projet | BM3: Charge (h) | BO3: Rang | BP3: Projet | BQ3: Charge (h) | BS3: Rang | BT3: Type | BU3: Charge (h) | BW3: Rang | BX3: Position dans Charge | BZ3: Ressource de la ligne (K sinon L) | CA3: Rang affaire du dessinateur sélectionné | CC3: Dessinateur sélectionné | CD3: Valeur | CF3: N° mois | CG3: Mois | CH3: Charge fixe (h) | CI3: Charge projets (h) | CJ3: Charge totale (h) | CK3: Capacité (h) | CL3: Projets dans la capacité (h) | CM3: Dépassement (h) | CN3: Marge (+) / dépassement (-) (h, total arrondi) | CO3: Occupation (total arrondi) | CP3: Charge totale arrondie (h) | CQ3: N° mois si surcharge | CS3: N° | CT3: Ressource | CU3: Capacité (h) | CV3: Charge fixe (h) | CW3: =W$3 -> 46266 | CX3: =X$3 -> 46296 | CY3: =Y$3 -> 46327 | CZ3: =Z$3 -> 46357 | DA3: =AA$3 -> 46388 | DB3: =AB$3 -> 46419 | DC3: =AC$3 -> 46447 | DD3: =AD$3 -> 46478 | ... DH3: =AH$3 -> 46600 | DI3: =W$3 -> 46266 | DJ3: =X$3 -> 46296 | DK3: =Y$3 -> 46327 | DL3: =Z$3 -> 46357 | DM3: =AA$3 -> 46388 | DN3: =AB$3 -> 46419 | DO3: =AC$3 -> 46447 | DP3: =AD$3 -> 46478 | ... DT3: =AH$3 -> 46600 | DU3: Occupation maximale | DV3: Charge projets sur la période (h) | DX3: Rang | DY3: Position dans Charge | DZ3: Projet | EA3: Sous-projet | EB3: Produit | EC3: Chef de projet | ED3: Charge (h) | EE3: Heures sur la période | EF3: Début planifié | EG3: Date de besoin | EH3: Avancement | EJ3: Dessinateurs Data (nettoyés) | EK3: Ressources externes Data (nettoyées) | EM3: Type de ressource de la ligne | EN3: Clé affaire (projet | sous-projet | produit) | EO3: 1re ligne de l'affaire | EP3: Charge de l'affaire (h) | EQ3: Rang de l'affaire | ER3: Personnes internes (distinctes) | ES3: Personnes externes (distinctes) | ET3: Ressources (texte) | EU3: Avancement de l'affaire (pondéré par les heures) | EV3: Début de la ligne (31/12/9999 = vide) | EW3: Début de l'affaire (le plus tôt) | EX3: Besoin de la ligne (0 = vide) | EY3: Besoin de l'affaire (le plus tard) | FA3: Ressources : dessinateurs puis externes (liste déroulante) | FB3: Type | FD3: Ligne avec dessinateur ET externe (1 = à corriger) | FE3: 1re ligne de cette ressource sur l'affaire
A4: =ROW() -> 4 | B4: =IF(TRIM(INDEX(Charge!$B:$B,ROW()))<>"",1,0) -> 1 | C4: =IF(B4=1,MIN(1,MAX(0,N(INDEX(Charge!$O:$O,ROW())))),0) -> 0.15 | D4: =IF(B4=1,IF(OR(p_Perimetre="Tous les projets",C4<1),1,0),0) -> 1 | E4: =IF(D4=1,MAX(0,N(INDEX(Charge!$M:$M,ROW()))),0) -> 300 | F4: =IF(D4=1,IF(TRIM(INDEX(Charge!$A:$A,ROW()))="","(non renseigné)",TRIM(INDEX(Charge!$A:$A,ROW()))),"") -> Julie Martin | G4: =IF(D4=1,TRIM(INDEX(Charge!$B:$B,ROW())),"") -> ATLAS | H4: =IF(D4=1,IF(TRIM(INDEX(Charge!$E:$E,ROW()))="","(non renseigné)",TRIM(INDEX(Charge!$E:$E,ROW()))),"") -> Étude de conception | I4: =IF(AND(D4=1,ISNUMBER(INDEX(Charge!$N:$N,ROW()))),INDEX(Charge!$N:$N,ROW()),"") -> 46328 | J4: =IF(I4="","",IF(AND(p_Repartition="Lissée jusqu'à la date de besoin",ISNUMBER(INDEX(Charge!$F:$F,ROW()))),IF(INDEX(Charge!$F:$F,ROW())>=I4,INDEX(Charge!$F:$F,ROW()),I4),I4)) -> 46477 | K4: =IF(I4="","",NETWORKDAYS(I4,J4,Data!$K$4:$K$203)) -> 108 | L4: =IF(D4=1,COUNTIFS($D$4:$D$503,1,$E$4:$E$503,">"&E4)+COUNTIFS($D$4:$D4,1,$E$4:$E4,E4),"") -> 2 | M4: =IF(F4="",0,IF(COUNTIF($F$4:F4,F4)=1,1,0)) -> 1 | N4: =IF(M4=1,ROUND(SUMIF($F$4:$F$503,F4,$E$4:$E$503),2),"") -> 860 | O4: =IF(M4=1,COUNTIFS($M$4:$M$503,1,$N$4:$N$503,">"&N4)+COUNTIFS($M$4:M4,1,$N$4:N4,N4),"") -> 1 | P4: =IF(G4="",0,IF(COUNTIF($G$4:G4,G4)=1,1,0)) -> 1 | Q4: =IF(P4=1,ROUND(SUMIF($G$4:$G$503,G4,$E$4:$E$503),2),"") -> 860 | R4: =IF(P4=1,COUNTIFS($P$4:$P$503,1,$Q$4:$Q$503,">"&Q4)+COUNTIFS($P$4:P4,1,$Q$4:Q4,Q4),"") -> 1 | S4: =IF(H4="",0,IF(COUNTIF($H$4:H4,H4)=1,1,0)) -> 1 | T4: =IF(S4=1,ROUND(SUMIF($H$4:$H$503,H4,$E$4:$E$503),2),"") -> 2030 | U4: =IF(S4=1,COUNTIFS($S$4:$S$503,1,$T$4:$T$503,">"&T4)+COUNTIFS($S$4:S4,1,$T$4:T4,T4),"") -> 1 | V4: =IF(D4=1,MIN(INDEX($R$4:$R$503,MATCH(G4,$G$4:$G$503,0)),IF($AL$7>9,9,999)),"") -> 1 | W4: =IF(OR($I4="",$E4=0),0,IF(OR($J4<W$3,$I4>W$2),0,IF($K4=0,IF(AND($I4>=W$3,$I4<=W$2),$E4,0),$E4*NETWORKDAYS(MAX($I4,W$3),MIN($J4,W$2),Data!$K$4:$K$203)/$K4))) -> 0 | X4: =IF(OR($I4="",$E4=0),0,IF(OR($J4<X$3,$I4>X$2),0,IF($K4=0,IF(AND($I4>=X$3,$I4<=X$2),$E4,0),$E4*NETWORKDAYS(MAX($I4,X$3),MIN($J4,X$2),Data!$K$4:$K$203)/$K4))) -> 0 | Y4: =IF(OR($I4="",$E4=0),0,IF(OR($J4<Y$3,$I4>Y$2),0,IF($K4=0,IF(AND($I4>=Y$3,$I4<=Y$2),$E4,0),$E4*NETWORKDAYS(MAX($I4,Y$3),MIN($J4,Y$2),Data!$K$4:$K$203)/$K4))) -> 58.333333 | Z4: =IF(OR($I4="",$E4=0),0,IF(OR($J4<Z$3,$I4>Z$2),0,IF($K4=0,IF(AND($I4>=Z$3,$I4<=Z$2),$E4,0),$E4*NETWORKDAYS(MAX($I4,Z$3),MIN($J4,Z$2),Data!$K$4:$K$203)/$K4))) -> 63.888889 | AA4: =IF(OR($I4="",$E4=0),0,IF(OR($J4<AA$3,$I4>AA$2),0,IF($K4=0,IF(AND($I4>=AA$3,$I4<=AA$2),$E4,0),$E4*NETWORKDAYS(MAX($I4,AA$3),MIN($J4,AA$2),Data!$K$4:$K$203)/$K4))) -> 58.333333 | AB4: =IF(OR($I4="",$E4=0),0,IF(OR($J4<AB$3,$I4>AB$2),0,IF($K4=0,IF(AND($I4>=AB$3,$I4<=AB$2),$E4,0),$E4*NETWORKDAYS(MAX($I4,AB$3),MIN($J4,AB$2),Data!$K$4:$K$203)/$K4))) -> 55.555556 | AC4: =IF(OR($I4="",$E4=0),0,IF(OR($J4<AC$3,$I4>AC$2),0,IF($K4=0,IF(AND($I4>=AC$3,$I4<=AC$2),$E4,0),$E4*NETWORKDAYS(MAX($I4,AC$3),MIN($J4,AC$2),Data!$K$4:$K$203)/$K4))) -> 63.888889 | AD4: =IF(OR($I4="",$E4=0),0,IF(OR($J4<AD$3,$I4>AD$2),0,IF($K4=0,IF(AND($I4>=AD$3,$I4<=AD$2),$E4,0),$E4*NETWORKDAYS(MAX($I4,AD$3),MIN($J4,AD$2),Data!$K$4:$K$203)/$K4))) -> 0 | ... AH4: =IF(OR($I4="",$E4=0),0,IF(OR($J4<AH$3,$I4>AH$2),0,IF($K4=0,IF(AND($I4>=AH$3,$I4<=AH$2),$E4,0),$E4*NETWORKDAYS(MAX($I4,AH$3),MIN($J4,AH$2),Data!$K$4:$K$203)/$K4))) -> 0 | AI4: =SUM(W4:AH4) -> 300 | AK4: Charge totale identifiée (h) | AL4: =SUM(E4:E503) -> 3455 | AN4: 1 | AO4: =W$3 -> 46266 | AP4: =SUM(W4:W503) -> 28.363636 | AQ4: =SUMPRODUCT((W4:W503>0)/(COUNTIFS($EN$4:$EN$503,$EN$4:$EN$503,W4:W503,">0")+(W4:W503<=0))) -> 1 | AS4: 1 | AT4: =IF(AS4>$AL$7,"",INDEX($G$4:$G$503,MATCH(AS4,$R$4:$R$503,0))) -> ATLAS | AU4: =SUMIF($V$4:$V$503,AS4,$E$4:$E$503) -> 860 | AV4: =IF($AL$4=0,0,AU4/$AL$4) -> 0.24891462 | AW4: =SUMIF($V$4:$V$503,$AS4,W$4:W$503) -> 0 | AX4: =SUMIF($V$4:$V$503,$AS4,X$4:X$503) -> 0 | AY4: =SUMIF($V$4:$V$503,$AS4,Y$4:Y$503) -> 81.666667 | AZ4: =SUMIF($V$4:$V$503,$AS4,Z$4:Z$503) -> 89.444444 | BA4: =SUMIF($V$4:$V$503,$AS4,AA$4:AA$503) -> 120.66667 | BB4: =SUMIF($V$4:$V$503,$AS4,AB$4:AB$503) -> 129.77778 | BC4: =SUMIF($V$4:$V$503,$AS4,AC$4:AC$503) -> 149.24444 | BD4: =SUMIF($V$4:$V$503,$AS4,AD$4:AD$503) -> 99.552941 | ... BH4: =SUMIF($V$4:$V$503,$AS4,AH$4:AH$503) -> 0 | BK4: 1 | BL4: =IF(BK4>$AL$6,"",INDEX($F$4:$F$503,MATCH(BK4,$O$4:$O$503,0))) -> Julie Martin | BM4: =IF(BL4="","",INDEX($N$4:$N$503,MATCH(BK4,$O$4:$O$503,0))) -> 860 | BO4: 1 | BP4: =IF(BO4>$AL$7,"",INDEX($G$4:$G$503,MATCH(BO4,$R$4:$R$503,0))) -> ATLAS | BQ4: =IF(BP4="","",INDEX($Q$4:$Q$503,MATCH(BO4,$R$4:$R$503,0))) -> 860 | BS4: 1 | BT4: =IF(BS4>$AL$8,"",INDEX($H$4:$H$503,MATCH(BS4,$U$4:$U$503,0))) -> Étude de conception | BU4: =IF(BT4="","",INDEX($T$4:$T$503,MATCH(BS4,$U$4:$U$503,0))) -> 2030 | BW4: 1 | BX4: =IFERROR(MATCH(BW4,$EQ$4:$EQ$503,0),"") -> 17 | BZ4: =IF(D4=1,IF(TRIM(INDEX(Charge!$K:$K,ROW()))<>"",TRIM(INDEX(Charge!$K:$K,ROW())),IF(TRIM(INDEX(Charge!$L:$L,ROW()))<>"",TRIM(INDEX(Charge!$L:$L,ROW())),"(non affecté)")),"") -> Lucas Garnier | CA4: =IF(AND($CD$4<>"",BZ4=$CD$4),COUNTIFS($BZ$4:$BZ$503,$CD$4,$L$4:$L$503,"<"&L4)+1,"") -> 1 | CC4: Ressource sélectionnée | CD4: =TRIM(p_Dessinateur) -> Lucas Garnier | CF4: 1 | CG4: =W$3 -> 46266 | CH4: =IF($CD$4="",0,$CD$7) -> 20 | CI4: =IF($CD$4="",0,SUMIF($BZ$4:$BZ$503,$CD$4,W$4:W$503)) -> 28.363636 | CJ4: =CH4+CI4 -> 48.363636 | CK4: =IF($CD$4="",0,$CD$6) -> 120 | CL4: =IF(CN4<0,MAX(0,MIN(CI4,CK4-CH4)),CI4) -> 28.363636 | CM4: =CI4-CL4 -> 0 | CN4: =CK4-CP4 -> 72 | CO4: =IF(CK4<=0,IF(CP4>0,9.99,0),CP4/CK4) -> 0.4 | CP4: =ROUND(CJ4,0) -> 48 | CQ4: =IF(CN4<0,CF4,"") | CS4: 1 | CT4: =IF(OR(FA4="",FALSE),"",FA4) -> Lucas Garnier | CU4: =IF(CT4="","",IF(FB4="Interne",IF(ISNUMBER(INDEX(Data!$F:$F,4)),INDEX(Data!$F:$F,4),p_HeuresETP),IF(ISNUMBER(INDEX(Data!$I:$I,4-$CD$23)),INDEX(Data!$I:$I,4-$CD$23),p_HeuresETP))) -> 120 | CV4: =IF(CT4="","",IF(FB4="Interne",IF(ISNUMBER(INDEX(Data!$G:$G,4)),INDEX(Data!$G:$G,4),p_ChargeFixe),IF(ISNUMBER(INDEX(Data!$J:$J,4-$CD$23)),INDEX(Data!$J:$J,4-$CD$23),p_ChargeFixe))) -> 20 | CW4: =IF($CT4="","",SUMIF($BZ$4:$BZ$503,$CT4,W$4:W$503)) -> 28.363636 | CX4: =IF($CT4="","",SUMIF($BZ$4:$BZ$503,$CT4,X$4:X$503)) -> 48 | CY4: =IF($CT4="","",SUMIF($BZ$4:$BZ$503,$CT4,Y$4:Y$503)) -> 101.9697 | CZ4: =IF($CT4="","",SUMIF($BZ$4:$BZ$503,$CT4,Z$4:Z$503)) -> 63.888889 | DA4: =IF($CT4="","",SUMIF($BZ$4:$BZ$503,$CT4,AA$4:AA$503)) -> 58.333333 | DB4: =IF($CT4="","",SUMIF($BZ$4:$BZ$503,$CT4,AB$4:AB$503)) -> 55.555556 | DC4: =IF($CT4="","",SUMIF($BZ$4:$BZ$503,$CT4,AC$4:AC$503)) -> 63.888889 | DD4: =IF($CT4="","",SUMIF($BZ$4:$BZ$503,$CT4,AD$4:AD$503)) -> 0 | ... DH4: =IF($CT4="","",SUMIF($BZ$4:$BZ$503,$CT4,AH$4:AH$503)) -> 0 | DI4: =IF($CT4="","",IF($CU4<=0,IF(ROUND($CV4+CW4,0)>0,9.99,0),ROUND($CV4+CW4,0)/$CU4)) -> 0.4 | DJ4: =IF($CT4="","",IF($CU4<=0,IF(ROUND($CV4+CX4,0)>0,9.99,0),ROUND($CV4+CX4,0)/$CU4)) -> 0.56666667 | DK4: =IF($CT4="","",IF($CU4<=0,IF(ROUND($CV4+CY4,0)>0,9.99,0),ROUND($CV4+CY4,0)/$CU4)) -> 1.0166667 | DL4: =IF($CT4="","",IF($CU4<=0,IF(ROUND($CV4+CZ4,0)>0,9.99,0),ROUND($CV4+CZ4,0)/$CU4)) -> 0.7 | DM4: =IF($CT4="","",IF($CU4<=0,IF(ROUND($CV4+DA4,0)>0,9.99,0),ROUND($CV4+DA4,0)/$CU4)) -> 0.65 | DN4: =IF($CT4="","",IF($CU4<=0,IF(ROUND($CV4+DB4,0)>0,9.99,0),ROUND($CV4+DB4,0)/$CU4)) -> 0.63333333 | DO4: =IF($CT4="","",IF($CU4<=0,IF(ROUND($CV4+DC4,0)>0,9.99,0),ROUND($CV4+DC4,0)/$CU4)) -> 0.7 | DP4: =IF($CT4="","",IF($CU4<=0,IF(ROUND($CV4+DD4,0)>0,9.99,0),ROUND($CV4+DD4,0)/$CU4)) -> 0.16666667 | ... DT4: =IF($CT4="","",IF($CU4<=0,IF(ROUND($CV4+DH4,0)>0,9.99,0),ROUND($CV4+DH4,0)/$CU4)) -> 0.16666667 | DU4: =IF(CT4="","",MAX(DI4:DT4)) -> 1.0166667 | DV4: =IF(CT4="","",SUM(CW4:DH4)) -> 420 | DX4: 1 | DY4: =IFERROR(MATCH(DX4,$CA$4:$CA$503,0),"") -> 1 | DZ4: =IF(DY4="","",INDEX(Charge!$B:$B,DY4+3)&"") -> ATLAS | EA4: =IF(DY4="","",INDEX(Charge!$C:$C,DY4+3)&"") -> Lot 1 – Structure | EB4: =IF(DY4="","",INDEX(Charge!$D:$D,DY4+3)&"") -> Châssis principal | EC4: =IF(DY4="","",INDEX(Charge!$A:$A,DY4+3)&"") -> Julie Martin | ED4: =IF(DY4="","",INDEX($E$4:$E$503,DY4)) -> 300 | EE4: =IF(DY4="","",INDEX($AI$4:$AI$503,DY4)) -> 300 | EF4: =IF(DY4="","",IF(ISNUMBER(INDEX(Charge!$N:$N,DY4+3)),INDEX(Charge!$N:$N,DY4+3),"—")) -> 46328 | EG4: =IF(DY4="","",IF(ISNUMBER(INDEX(Charge!$F:$F,DY4+3)),INDEX(Charge!$F:$F,DY4+3),"—")) -> 46477 | EH4: =IF(DY4="","",INDEX($C$4:$C$503,DY4)) -> 0.15 | EJ4: =TRIM(INDEX(Data!$E:$E,ROW())) -> Lucas Garnier | EK4: =TRIM(INDEX(Data!$H:$H,ROW())) -> Paul Girard | EM4: =IF(D4=1,IF(TRIM(INDEX(Charge!$K:$K,ROW()))<>"","Interne",IF(TRIM(INDEX(Charge!$L:$L,ROW()))<>"","Externe","Non affecté")),"") -> Interne | EN4: =IF(D4=1,LEFT(SUBSTITUTE(SUBSTITUTE(SUBSTITUTE(TRIM(SUBSTITUTE(INDEX(Charge!$B:$B,ROW()),CHAR(160)," "))&" | "&TRIM(SUBSTITUTE(INDEX(Charge!$C:$C,ROW()),CHAR(160)," "))&" | "&TRIM(SUBSTITUTE(INDEX(Charge!$D:$D,ROW()),CHAR(160)," ")),"~","-"),"*","+"),"?","!"),240),"") -> ATLAS | Lot 1 – Structure | Châssis principal | EO4: =IF(EN4="",0,IF(COUNTIF($EN$4:EN4,EN4)=1,1,0)) -> 1 | EP4: =IF(EO4=1,ROUND(SUMIF($EN$4:$EN$503,EN4,$E$4:$E$503),2),"") -> 420 | EQ4: =IF(EO4=1,COUNTIFS($EO$4:$EO$503,1,$EP$4:$EP$503,">"&EP4)+COUNTIFS($EO$4:EO4,1,$EP$4:EP4,EP4),"") -> 2 | ER4: =IF(EO4=1,COUNTIFS($EN$4:$EN$503,EN4,$EM$4:$EM$503,"Interne",$FE$4:$FE$503,1),"") -> 1 | ES4: =IF(EO4=1,COUNTIFS($EN$4:$EN$503,EN4,$EM$4:$EM$503,"Externe",$FE$4:$FE$503,1),"") -> 1 | ET4: =IF(EO4=1,IF(ER4+ES4=0,"à affecter",IF(ER4=0,ES4&" ext.",(ER4+ES4)&IF(ES4>0," dont "&ES4&" ext.",""))&IF(COUNTIFS($EN$4:$EN$503,EN4,$EM$4:$EM$503,"Non affecté")>0," + à affecter","")),"") -> 2 dont 1 ext. | EU4: =IF(EO4=1,IF(EP4>0,SUMPRODUCT(($EN$4:$EN$503=EN4)*$E$4:$E$503*$C$4:$C$503)/EP4,AVERAGEIF($EN$4:$EN$503,EN4,$C$4:$C$503)),"") -> 0.10714286 | EV4: =IF(ISNUMBER(I4),I4,2958465) -> 46328 | EW4: =IF(EO4=1,SUMPRODUCT(MIN(($EN$4:$EN$503=EN4)*$EV$4:$EV$503+($EN$4:$EN$503<>EN4)*2958465)),"") -> 46328 | EX4: =IF(AND(D4=1,ISNUMBER(INDEX(Charge!$F:$F,ROW()))),INDEX(Charge!$F:$F,ROW()),0) -> 46477 | EY4: =IF(EO4=1,SUMPRODUCT(MAX(($EN$4:$EN$503=EN4)*$EX$4:$EX$503)),"") -> 46477 | FA4: =IF(1<=$CD$23,INDEX($EJ$4:$EJ$203,1),IF(1-$CD$23<=$CD$26,INDEX($EK$4:$EK$203,1-$CD$23),"")) -> Lucas Garnier | FB4: =IF(FA4="","",IF(1<=$CD$23,"Interne","Externe")) -> Interne | FD4: =IF(AND(B4=1,TRIM(INDEX(Charge!$K:$K,ROW()))<>"",TRIM(INDEX(Charge!$L:$L,ROW()))<>""),1,0) -> 0 | FE4: =IF(OR(EN4="",BZ4="(non affecté)"),0,IF(COUNTIFS($EN$4:EN4,EN4,$BZ$4:BZ4,BZ4)=1,1,0)) -> 1
A5: =ROW() -> 5 | B5: =IF(TRIM(INDEX(Charge!$B:$B,ROW()))<>"",1,0) -> 1 | C5: =IF(B5=1,MIN(1,MAX(0,N(INDEX(Charge!$O:$O,ROW())))),0) -> 0 | D5: =IF(B5=1,IF(OR(p_Perimetre="Tous les projets",C5<1),1,0),0) -> 1 | E5: =IF(D5=1,MAX(0,N(INDEX(Charge!$M:$M,ROW()))),0) -> 120 | F5: =IF(D5=1,IF(TRIM(INDEX(Charge!$A:$A,ROW()))="","(non renseigné)",TRIM(INDEX(Charge!$A:$A,ROW()))),"") -> Julie Martin | G5: =IF(D5=1,TRIM(INDEX(Charge!$B:$B,ROW())),"") -> ATLAS | H5: =IF(D5=1,IF(TRIM(INDEX(Charge!$E:$E,ROW()))="","(non renseigné)",TRIM(INDEX(Charge!$E:$E,ROW()))),"") -> Étude de conception | I5: =IF(AND(D5=1,ISNUMBER(INDEX(Charge!$N:$N,ROW()))),INDEX(Charge!$N:$N,ROW()),"") -> 46328 | J5: =IF(I5="","",IF(AND(p_Repartition="Lissée jusqu'à la date de besoin",ISNUMBER(INDEX(Charge!$F:$F,ROW()))),IF(INDEX(Charge!$F:$F,ROW())>=I5,INDEX(Charge!$F:$F,ROW()),I5),I5)) -> 46477 | K5: =IF(I5="","",NETWORKDAYS(I5,J5,Data!$K$4:$K$203)) -> 108 | L5: =IF(D5=1,COUNTIFS($D$4:$D$503,1,$E$4:$E$503,">"&E5)+COUNTIFS($D$4:$D5,1,$E$4:$E5,E5),"") -> 12 | M5: =IF(F5="",0,IF(COUNTIF($F$4:F5,F5)=1,1,0)) -> 0 | N5: =IF(M5=1,ROUND(SUMIF($F$4:$F$503,F5,$E$4:$E$503),2),"") | O5: =IF(M5=1,COUNTIFS($M$4:$M$503,1,$N$4:$N$503,">"&N5)+COUNTIFS($M$4:M5,1,$N$4:N5,N5),"") | P5: =IF(G5="",0,IF(COUNTIF($G$4:G5,G5)=1,1,0)) -> 0 | Q5: =IF(P5=1,ROUND(SUMIF($G$4:$G$503,G5,$E$4:$E$503),2),"") | R5: =IF(P5=1,COUNTIFS($P$4:$P$503,1,$Q$4:$Q$503,">"&Q5)+COUNTIFS($P$4:P5,1,$Q$4:Q5,Q5),"") | S5: =IF(H5="",0,IF(COUNTIF($H$4:H5,H5)=1,1,0)) -> 0 | T5: =IF(S5=1,ROUND(SUMIF($H$4:$H$503,H5,$E$4:$E$503),2),"") | U5: =IF(S5=1,COUNTIFS($S$4:$S$503,1,$T$4:$T$503,">"&T5)+COUNTIFS($S$4:S5,1,$T$4:T5,T5),"") | V5: =IF(D5=1,MIN(INDEX($R$4:$R$503,MATCH(G5,$G$4:$G$503,0)),IF($AL$7>9,9,999)),"") -> 1 | W5: =IF(OR($I5="",$E5=0),0,IF(OR($J5<W$3,$I5>W$2),0,IF($K5=0,IF(AND($I5>=W$3,$I5<=W$2),$E5,0),$E5*NETWORKDAYS(MAX($I5,W$3),MIN($J5,W$2),Data!$K$4:$K$203)/$K5))) -> 0 | X5: =IF(OR($I5="",$E5=0),0,IF(OR($J5<X$3,$I5>X$2),0,IF($K5=0,IF(AND($I5>=X$3,$I5<=X$2),$E5,0),$E5*NETWORKDAYS(MAX($I5,X$3),MIN($J5,X$2),Data!$K$4:$K$203)/$K5))) -> 0 | Y5: =IF(OR($I5="",$E5=0),0,IF(OR($J5<Y$3,$I5>Y$2),0,IF($K5=0,IF(AND($I5>=Y$3,$I5<=Y$2),$E5,0),$E5*NETWORKDAYS(MAX($I5,Y$3),MIN($J5,Y$2),Data!$K$4:$K$203)/$K5))) -> 23.333333 | Z5: =IF(OR($I5="",$E5=0),0,IF(OR($J5<Z$3,$I5>Z$2),0,IF($K5=0,IF(AND($I5>=Z$3,$I5<=Z$2),$E5,0),$E5*NETWORKDAYS(MAX($I5,Z$3),MIN($J5,Z$2),Data!$K$4:$K$203)/$K5))) -> 25.555556 | AA5: =IF(OR($I5="",$E5=0),0,IF(OR($J5<AA$3,$I5>AA$2),0,IF($K5=0,IF(AND($I5>=AA$3,$I5<=AA$2),$E5,0),$E5*NETWORKDAYS(MAX($I5,AA$3),MIN($J5,AA$2),Data!$K$4:$K$203)/$K5))) -> 23.333333 | AB5: =IF(OR($I5="",$E5=0),0,IF(OR($J5<AB$3,$I5>AB$2),0,IF($K5=0,IF(AND($I5>=AB$3,$I5<=AB$2),$E5,0),$E5*NETWORKDAYS(MAX($I5,AB$3),MIN($J5,AB$2),Data!$K$4:$K$203)/$K5))) -> 22.222222 | AC5: =IF(OR($I5="",$E5=0),0,IF(OR($J5<AC$3,$I5>AC$2),0,IF($K5=0,IF(AND($I5>=AC$3,$I5<=AC$2),$E5,0),$E5*NETWORKDAYS(MAX($I5,AC$3),MIN($J5,AC$2),Data!$K$4:$K$203)/$K5))) -> 25.555556 | AD5: =IF(OR($I5="",$E5=0),0,IF(OR($J5<AD$3,$I5>AD$2),0,IF($K5=0,IF(AND($I5>=AD$3,$I5<=AD$2),$E5,0),$E5*NETWORKDAYS(MAX($I5,AD$3),MIN($J5,AD$2),Data!$K$4:$K$203)/$K5))) -> 0 | ... AH5: =IF(OR($I5="",$E5=0),0,IF(OR($J5<AH$3,$I5>AH$2),0,IF($K5=0,IF(AND($I5>=AH$3,$I5<=AH$2),$E5,0),$E5*NETWORKDAYS(MAX($I5,AH$3),MIN($J5,AH$2),Data!$K$4:$K$203)/$K5))) -> 0 | AI5: =SUM(W5:AH5) -> 120 | AK5: Nombre d'affaires (sous-projets regroupés) | AL5: =SUM(EO4:EO503) -> 17 | AN5: 2 | AO5: =X$3 -> 46296 | AP5: =SUM(X4:X503) -> 165.94118 | AQ5: =SUMPRODUCT((X4:X503>0)/(COUNTIFS($EN$4:$EN$503,$EN$4:$EN$503,X4:X503,">0")+(X4:X503<=0))) -> 3 | AS5: 2 | AT5: =IF(AS5>$AL$7,"",INDEX($G$4:$G$503,MATCH(AS5,$R$4:$R$503,0))) -> BORÉAL | AU5: =SUMIF($V$4:$V$503,AS5,$E$4:$E$503) -> 620 | AV5: =IF($AL$4=0,0,AU5/$AL$4) -> 0.17945007 | AW5: =SUMIF($V$4:$V$503,$AS5,W$4:W$503) -> 0 | AX5: =SUMIF($V$4:$V$503,$AS5,X$4:X$503) -> 72.941176 | AY5: =SUMIF($V$4:$V$503,$AS5,Y$4:Y$503) -> 76.588235 | AZ5: =SUMIF($V$4:$V$503,$AS5,Z$4:Z$503) -> 83.882353 | BA5: =SUMIF($V$4:$V$503,$AS5,AA$4:AA$503) -> 98.539455 | BB5: =SUMIF($V$4:$V$503,$AS5,AB$4:AB$503) -> 111.59475 | BC5: =SUMIF($V$4:$V$503,$AS5,AC$4:AC$503) -> 101.9925 | BD5: =SUMIF($V$4:$V$503,$AS5,AD$4:AD$503) -> 74.461538 | ... BH5: =SUMIF($V$4:$V$503,$AS5,AH$4:AH$503) -> 0 | BK5: 2 | BL5: =IF(BK5>$AL$6,"",INDEX($F$4:$F$503,MATCH(BK5,$O$4:$O$503,0))) -> Thomas Bernard | BM5: =IF(BL5="","",INDEX($N$4:$N$503,MATCH(BK5,$O$4:$O$503,0))) -> 820 | BO5: 2 | BP5: =IF(BO5>$AL$7,"",INDEX($G$4:$G$503,MATCH(BO5,$R$4:$R$503,0))) -> BORÉAL | BQ5: =IF(BP5="","",INDEX($Q$4:$Q$503,MATCH(BO5,$R$4:$R$503,0))) -> 620 | BS5: 2 | BT5: =IF(BS5>$AL$8,"",INDEX($H$4:$H$503,MATCH(BS5,$U$4:$U$503,0))) -> Industrialisation | BU5: =IF(BT5="","",INDEX($T$4:$T$503,MATCH(BS5,$U$4:$U$503,0))) -> 540 | BW5: 2 | BX5: =IFERROR(MATCH(BW5,$EQ$4:$EQ$503,0),"") -> 1 | BZ5: =IF(D5=1,IF(TRIM(INDEX(Charge!$K:$K,ROW()))<>"",TRIM(INDEX(Charge!$K:$K,ROW())),IF(TRIM(INDEX(Charge!$L:$L,ROW()))<>"",TRIM(INDEX(Charge!$L:$L,ROW())),"(non affecté)")),"") -> Paul Girard | CA5: =IF(AND($CD$4<>"",BZ5=$CD$4),COUNTIFS($BZ$4:$BZ$503,$CD$4,$L$4:$L$503,"<"&L5)+1,"") | CC5: Position dans la liste des dessinateurs (0 = absent) | CD5: =IF(CD4="",0,IFERROR(MATCH(CD4,$EJ$4:$EJ$203,0),0)) -> 1 | CF5: 2 | CG5: =X$3 -> 46296 | CH5: =IF($CD$4="",0,$CD$7) -> 20 | CI5: =IF($CD$4="",0,SUMIF($BZ$4:$BZ$503,$CD$4,X$4:X$503)) -> 48 | CJ5: =CH5+CI5 -> 68 | CK5: =IF($CD$4="",0,$CD$6) -> 120 | CL5: =IF(CN5<0,MAX(0,MIN(CI5,CK5-CH5)),CI5) -> 48 | CM5: =CI5-CL5 -> 0 | CN5: =CK5-CP5 -> 52 | CO5: =IF(CK5<=0,IF(CP5>0,9.99,0),CP5/CK5) -> 0.56666667 | CP5: =ROUND(CJ5,0) -> 68 | CQ5: =IF(CN5<0,CF5,"") | CS5: 2 | CT5: =IF(OR(FA5="",COUNTIF($FA$4:FA4,FA5)>0),"",FA5) -> Emma Faure | CU5: =IF(CT5="","",IF(FB5="Interne",IF(ISNUMBER(INDEX(Data!$F:$F,5)),INDEX(Data!$F:$F,5),p_HeuresETP),IF(ISNUMBER(INDEX(Data!$I:$I,5-$CD$23)),INDEX(Data!$I:$I,5-$CD$23),p_HeuresETP))) -> 120 | CV5: =IF(CT5="","",IF(FB5="Interne",IF(ISNUMBER(INDEX(Data!$G:$G,5)),INDEX(Data!$G:$G,5),p_ChargeFixe),IF(ISNUMBER(INDEX(Data!$J:$J,5-$CD$23)),INDEX(Data!$J:$J,5-$CD$23),p_ChargeFixe))) -> 20 | CW5: =IF($CT5="","",SUMIF($BZ$4:$BZ$503,$CT5,W$4:W$503)) -> 0 | CX5: =IF($CT5="","",SUMIF($BZ$4:$BZ$503,$CT5,X$4:X$503)) -> 0 | CY5: =IF($CT5="","",SUMIF($BZ$4:$BZ$503,$CT5,Y$4:Y$503)) -> 0 | CZ5: =IF($CT5="","",SUMIF($BZ$4:$BZ$503,$CT5,Z$4:Z$503)) -> 57.5 | DA5: =IF($CT5="","",SUMIF($BZ$4:$BZ$503,$CT5,AA$4:AA$503)) -> 91.5 | DB5: =IF($CT5="","",SUMIF($BZ$4:$BZ$503,$CT5,AB$4:AB$503)) -> 102 | DC5: =IF($CT5="","",SUMIF($BZ$4:$BZ$503,$CT5,AC$4:AC$503)) -> 126.70909 | DD5: =IF($CT5="","",SUMIF($BZ$4:$BZ$503,$CT5,AD$4:AD$503)) -> 121.2 | ... DH5: =IF($CT5="","",SUMIF($BZ$4:$BZ$503,$CT5,AH$4:AH$503)) -> 28.235294 | DI5: =IF($CT5="","",IF($CU5<=0,IF(ROUND($CV5+CW5,0)>0,9.99,0),ROUND($CV5+CW5,0)/$CU5)) -> 0.16666667 | DJ5: =IF($CT5="","",IF($CU5<=0,IF(ROUND($CV5+CX5,0)>0,9.99,0),ROUND($CV5+CX5,0)/$CU5)) -> 0.16666667 | DK5: =IF($CT5="","",IF($CU5<=0,IF(ROUND($CV5+CY5,0)>0,9.99,0),ROUND($CV5+CY5,0)/$CU5)) -> 0.16666667 | DL5: =IF($CT5="","",IF($CU5<=0,IF(ROUND($CV5+CZ5,0)>0,9.99,0),ROUND($CV5+CZ5,0)/$CU5)) -> 0.65 | DM5: =IF($CT5="","",IF($CU5<=0,IF(ROUND($CV5+DA5,0)>0,9.99,0),ROUND($CV5+DA5,0)/$CU5)) -> 0.93333333 | DN5: =IF($CT5="","",IF($CU5<=0,IF(ROUND($CV5+DB5,0)>0,9.99,0),ROUND($CV5+DB5,0)/$CU5)) -> 1.0166667 | DO5: =IF($CT5="","",IF($CU5<=0,IF(ROUND($CV5+DC5,0)>0,9.99,0),ROUND($CV5+DC5,0)/$CU5)) -> 1.225 | DP5: =IF($CT5="","",IF($CU5<=0,IF(ROUND($CV5+DD5,0)>0,9.99,0),ROUND($CV5+DD5,0)/$CU5)) -> 1.175 | ... DT5: =IF($CT5="","",IF($CU5<=0,IF(ROUND($CV5+DH5,0)>0,9.99,0),ROUND($CV5+DH5,0)/$CU5)) -> 0.4 | DU5: =IF(CT5="","",MAX(DI5:DT5)) -> 1.225 | DV5: =IF(CT5="","",SUM(CW5:DH5)) -> 700 | DX5: 2 | DY5: =IFERROR(MATCH(DX5,$CA$4:$CA$503,0),"") -> 13 | DZ5: =IF(DY5="","",INDEX(Charge!$B:$B,DY5+3)&"") -> ORION | EA5: =IF(DY5="","",INDEX(Charge!$C:$C,DY5+3)&"") -> Tranche 1 | EB5: =IF(DY5="","",INDEX(Charge!$D:$D,DY5+3)&"") -> Support moteur | EC5: =IF(DY5="","",INDEX(Charge!$A:$A,DY5+3)&"") -> Nicolas Moreau | ED5: =IF(DY5="","",INDEX($E$4:$E$503,DY5)) -> 120 | EE5: =IF(DY5="","",INDEX($AI$4:$AI$503,DY5)) -> 120 | EF5: =IF(DY5="","",IF(ISNUMBER(INDEX(Charge!$N:$N,DY5+3)),INDEX(Charge!$N:$N,DY5+3),"—")) -> 46279 | EG5: =IF(DY5="","",IF(ISNUMBER(INDEX(Charge!$F:$F,DY5+3)),INDEX(Charge!$F:$F,DY5+3),"—")) -> 46353 | EH5: =IF(DY5="","",INDEX($C$4:$C$503,DY5)) -> 0.8 | EJ5: =TRIM(INDEX(Data!$E:$E,ROW())) -> Emma Faure | EK5: =TRIM(INDEX(Data!$H:$H,ROW())) -> Inès Morel | EM5: =IF(D5=1,IF(TRIM(INDEX(Charge!$K:$K,ROW()))<>"","Interne",IF(TRIM(INDEX(Charge!$L:$L,ROW()))<>"","Externe","Non affecté")),"") -> Externe | EN5: =IF(D5=1,LEFT(SUBSTITUTE(SUBSTITUTE(SUBSTITUTE(TRIM(SUBSTITUTE(INDEX(Charge!$B:$B,ROW()),CHAR(160)," "))&" | "&TRIM(SUBSTITUTE(INDEX(Charge!$C:$C,ROW()),CHAR(160)," "))&" | "&TRIM(SUBSTITUTE(INDEX(Charge!$D:$D,ROW()),CHAR(160)," ")),"~","-"),"*","+"),"?","!"),240),"") -> ATLAS | Lot 1 – Structure | Châssis principal | EO5: =IF(EN5="",0,IF(COUNTIF($EN$4:EN5,EN5)=1,1,0)) -> 0 | EP5: =IF(EO5=1,ROUND(SUMIF($EN$4:$EN$503,EN5,$E$4:$E$503),2),"") | EQ5: =IF(EO5=1,COUNTIFS($EO$4:$EO$503,1,$EP$4:$EP$503,">"&EP5)+COUNTIFS($EO$4:EO5,1,$EP$4:EP5,EP5),"") | ER5: =IF(EO5=1,COUNTIFS($EN$4:$EN$503,EN5,$EM$4:$EM$503,"Interne",$FE$4:$FE$503,1),"") | ES5: =IF(EO5=1,COUNTIFS($EN$4:$EN$503,EN5,$EM$4:$EM$503,"Externe",$FE$4:$FE$503,1),"") | ET5: =IF(EO5=1,IF(ER5+ES5=0,"à affecter",IF(ER5=0,ES5&" ext.",(ER5+ES5)&IF(ES5>0," dont "&ES5&" ext.",""))&IF(COUNTIFS($EN$4:$EN$503,EN5,$EM$4:$EM$503,"Non affecté")>0," + à affecter","")),"") | EU5: =IF(EO5=1,IF(EP5>0,SUMPRODUCT(($EN$4:$EN$503=EN5)*$E$4:$E$503*$C$4:$C$503)/EP5,AVERAGEIF($EN$4:$EN$503,EN5,$C$4:$C$503)),"") | EV5: =IF(ISNUMBER(I5),I5,2958465) -> 46328 | EW5: =IF(EO5=1,SUMPRODUCT(MIN(($EN$4:$EN$503=EN5)*$EV$4:$EV$503+($EN$4:$EN$503<>EN5)*2958465)),"") | EX5: =IF(AND(D5=1,ISNUMBER(INDEX(Charge!$F:$F,ROW()))),INDEX(Charge!$F:$F,ROW()),0) -> 46477 | EY5: =IF(EO5=1,SUMPRODUCT(MAX(($EN$4:$EN$503=EN5)*$EX$4:$EX$503)),"") | FA5: =IF(2<=$CD$23,INDEX($EJ$4:$EJ$203,2),IF(2-$CD$23<=$CD$26,INDEX($EK$4:$EK$203,2-$CD$23),"")) -> Emma Faure | FB5: =IF(FA5="","",IF(2<=$CD$23,"Interne","Externe")) -> Interne | FD5: =IF(AND(B5=1,TRIM(INDEX(Charge!$K:$K,ROW()))<>"",TRIM(INDEX(Charge!$L:$L,ROW()))<>""),1,0) -> 0 | FE5: =IF(OR(EN5="",BZ5="(non affecté)"),0,IF(COUNTIFS($EN$4:EN5,EN5,$BZ$4:BZ5,BZ5)=1,1,0)) -> 1
